<?xml version="1.0" ?>
<robot name="robot">
    
    
    
    
    
    
    
    
    
    
    
    
    
    
    
    
    
    
    <link name="b_CraneBody2_001_">
        
        
        
        
        
        
        
        
        
        
        
        
        
        
        
        
        
        
        <visual>
            
            
            
            
            
            
            
            
            
            
            
            
            
            
            
            
            
            
            <geometry>
                
                
                
                
                
                
                
                
                
                
                
                
                
                
                
                
                
                
                <mesh filename="b_CraneBody2_001_.obj"/>
                
                
                
                
                
                
                
                
                
            
            
            
            
            
            
            
            
            
            </geometry>
            
            
            
            
            
            
            
            
            
            
            
            
            
            
            
            
            
            
            <origin xyz="0 0 0" rpy="0 0 0"/>
            
            
            
            
            
            
            
            
            
            
            
            
            
            
            
            
            
            
            <material name="visual_material">
                
                
                
                
                
                
                
                
                
                
                
                
                
                
                
                
                
                
                <color rgba="1 0 0 1"/>
                
                
                
                
                
                
                
                
                
            
            
            
            
            
            
            
            
            
            </material>
            
            
            
            
            
            
            
            
            
        
        
        
        
        
        
        
        
        
        </visual>
        
        
        
        
        
        
        
        
        
        
        
        
        
        
        
        
        
        
        <inertial>
            
            
            
            
            
            
            
            
            
            
            
            
            
            
            
            
            
            
            <mass value="1"/>
            
            
            
            
            
            
            
            
            
            
            
            
            
            
            
            
            
            
            <origin xyz="0 0 0" rpy="0 0 0"/>
            
            
            
            
            
            
            
            
            
            
            
            
            
            
            
            
            
            
            <inertia ixx="1" ixy="0" ixz="0" iyy="1" iyz="0" izz="1"/>
            
            
            
            
            
            
            
            
            
        
        
        
        
        
        
        
        
        
        </inertial>
        
        
        
        
        
        
        
        
        
        
        
        
        
        
        
        
        
        
        <collision>
            
            
            
            
            
            
            
            
            
            
            
            
            
            
            
            
            
            
            <geometry>
                
                
                
                
                
                
                
                
                
                
                
                
                
                
                
                
                
                
                <mesh filename="b_CraneBody2_001_.obj"/>
                
                
                
                
                
                
                
                
                
            
            
            
            
            
            
            
            
            
            </geometry>
            
            
            
            
            
            
            
            
            
            
            
            
            
            
            
            
            
            
            <origin xyz="0 0 0" rpy="0 0 0"/>
            
            
            
            
            
            
            
            
            
        
        
        
        
        
        
        
        
        
        </collision>
        
        
        
        
        
        
        
        
        
    
    
    
    
    
    
    
    
    
    </link>
    
    
    
    
    
    
    
    
    
    
    
    
    
    
    
    
    
    
    <joint name="Revolute_continuous_001" type="continuous">
        
        
        
        
        
        
        
        
        
        
        
        
        
        
        
        
        
        
        <parent link="b_CraneBody2_001_"/>
        
        
        
        
        
        
        
        
        
        
        
        
        
        
        
        
        
        
        <child link="b_Platform_001_"/>
        
        
        
        
        
        
        
        
        
        
        
        
        
        
        
        
        
        
        <origin rpy="0 0 0" xyz="17.041439 -19.999999999999996 17.914147999999997"/>
        
        
        
        
        
        
        
        
        
        
        
        
        
        
        
        
        
        
        <axis xyz="0.0 0.0 1.0"/>
        
        
        
        
        
        
        
        
        
        
        
        
        
        
        
        
        
        
        <limit velocity="10000000"/>
        
        
        
        
        
        
        
        
        
    
    
    
    
    
    
    
    
    
    </joint>
    
    
    
    
    
    
    
    
    
    
    
    
    
    
    
    
    
    
    <link name="b_Platform_001_">
        
        
        
        
        
        
        
        
        
        
        
        
        
        
        
        
        
        
        <visual>
            
            
            
            
            
            
            
            
            
            
            
            
            
            
            
            
            
            
            <origin xyz="-17.041439 19.999999999999996 -17.914147999999997" rpy="0 0 0"/>
            
            
            
            
            
            
            
            
            
            
            
            
            
            
            
            
            
            
            <geometry>
                
                
                
                
                
                
                
                
                
                
                
                
                
                
                
                
                
                
                <mesh filename="b_Platform_001_.obj"/>
                
                
                
                
                
                
                
                
                
            
            
            
            
            
            
            
            
            
            </geometry>
            
            
            
            
            
            
            
            
            
        
        
        
        
        
        
        
        
        
        </visual>
        
        
        
        
        
        
        
        
        
        
        
        
        
        
        
        
        
        
        <inertial>
            
            
            
            
            
            
            
            
            
            
            
            
            
            
            
            
            
            
            <mass value="1"/>
            
            
            
            
            
            
            
            
            
            
            
            
            
            
            
            
            
            
            <origin xyz="0 0 0"/>
            
            
            
            
            
            
            
            
            
            
            
            
            
            
            
            
            
            
            <inertia ixx="1498827.079055" ixy="-0.000000" ixz="-42868.859345" iyy="4581820.367100" iyz="0.000000" izz="5206073.491929"/>
            
            
            
            
            
            
            
            
            
        
        
        
        
        
        
        
        
        
        </inertial>
        
        
        
        
        
        
        
        
        
        
        
        
        
        
        
        
        
        
        <collision>
            
            
            
            
            
            
            
            
            
            
            
            
            
            
            
            
            
            
            <geometry>
                
                
                
                
                
                
                
                
                
                
                
                
                
                
                
                
                
                
                <mesh filename="b_Platform_001_.obj"/>
                
                
                
                
                
                
                
                
                
            
            
            
            
            
            
            
            
            
            </geometry>
            
            
            
            
            
            
            
            
            
            
            
            
            
            
            
            
            
            
            <origin xyz="-17.041439 19.999999999999996 -17.914147999999997" rpy="0 0 0"/>
            
            
            
            
            
            
            
            
            
        
        
        
        
        
        
        
        
        
        </collision>
        
        
        
        
        
        
        
        
        
    
    
    
    
    
    
    
    
    
    </link>
    
    
    
    
    
    
    
    
    

    
    
    
    
    
    
    
    
    <joint name="Revolute_continuous_002" type="continuous">
        
        
        
        
        
        
        
        
        
        
        
        
        
        
        
        
        <parent link="b_Platform_001_"/>
        
        
        
        
        
        
        
        
        
        
        
        
        
        
        
        
        <child link="b_Boom_001_"/>
        
        
        
        
        
        
        
        
        
        
        
        
        
        
        
        
        <origin rpy="0 0 0" xyz="24.99999859805587 1.0430812871220496e-06 19.285852000000006"/>
        
        
        
        
        
        
        
        
        
        
        
        
        
        
        
        
        <axis xyz="0.0 -1.0 0.0"/>
        
        
        
        
        
        
        
        
        
        
        
        
        
        
        
        
        <limit velocity="10000000"/>
        
        
        
        
        
        
        
        
    
    
    
    
    
    
    
    
    </joint>
    
    
    
    
    
    
    
    
    
    
    
    
    
    
    
    
    <link name="b_Boom_001_">
        
        
        
        
        
        
        
        
        
        
        
        
        
        
        
        
        <visual>
            
            
            
            
            
            
            
            
            
            
            
            
            
            
            
            
            <origin xyz="-42.04143759805587 19.99999895691871 -37.2" rpy="0 0 0"/>
            
            
            
            
            
            
            
            
            
            
            
            
            
            
            
            
            <geometry>
                
                
                
                
                
                
                
                
                
                
                
                
                
                
                
                
                <mesh filename="b_Boom_001_.obj"/>
                
                
                
                
                
                
                
                
            
            
            
            
            
            
            
            
            </geometry>
            
            
            
            
            
            
            
            
        
        
        
        
        
        
        
        
        </visual>
        
        
        
        
        
        
        
        
        
        
        
        
        
        
        
        
        <inertial>
            
            
            
            
            
            
            
            
            
            
            
            
            
            
            
            
            <mass value="1"/>
            
            
            
            
            
            
            
            
            
            
            
            
            
            
            
            
            <origin xyz="0 0 0"/>
            
            
            
            
            
            
            
            
            
            
            
            
            
            
            
            
            <inertia ixx="181737.171711" ixy="-0.098521" ixz="80710.850272" iyy="13738990.317884" iyz="-0.027699" izz="13702235.851209"/>
            
            
            
            
            
            
            
            
        
        
        
        
        
        
        
        
        </inertial>
        
        
        
        
        
        
        
        
        
        
        
        
        
        
        
        
        <collision>
            
            
            
            
            
            
            
            
            
            
            
            
            
            
            
            
            <geometry>
                
                
                
                
                
                
                
                
                
                
                
                
                
                
                
                
                <mesh filename="b_Boom_001_.obj"/>
                
                
                
                
                
                
                
                
            
            
            
            
            
            
            
            
            </geometry>
            
            
            
            
            
            
            
            
            
            
            
            
            
            
            
            
            <origin xyz="-42.04143759805587 19.99999895691871 -37.2" rpy="0 0 0"/>
            
            
            
            
            
            
            
            
        
        
        
        
        
        
        
        
        </collision>
        
        
        
        
        
        
        
        
    
    
    
    
    
    
    
    
    </link>
    
    
    
    
    
    
    
    

    
    
    
    
    
    
    
    <joint name="Revolute_continuous_003" type="continuous">
        
        
        
        
        
        
        
        
        
        
        
        
        
        
        <parent link="b_CraneBody2_001_"/>
        
        
        
        
        
        
        
        
        
        
        
        
        
        
        <child link="b_WheelTurner_001_"/>
        
        
        
        
        
        
        
        
        
        
        
        
        
        
        <origin rpy="0 0 0" xyz="-47.1506 -10.0 8.006339732172128"/>
        
        
        
        
        
        
        
        
        
        
        
        
        
        
        <axis xyz="0.0 0.0 1.0"/>
        
        
        
        
        
        
        
        
        
        
        
        
        
        
        <limit velocity="10000000"/>
        
        
        
        
        
        
        
    
    
    
    
    
    
    
    </joint>
    
    
    
    
    
    
    
    
    
    
    
    
    
    
    <link name="b_WheelTurner_001_">
        
        
        
        
        
        
        
        
        
        
        
        
        
        
        <visual>
            
            
            
            
            
            
            
            
            
            
            
            
            
            
            <origin xyz="47.1506 10.0 -8.006339732172128" rpy="0 0 0"/>
            
            
            
            
            
            
            
            
            
            
            
            
            
            
            <geometry>
                
                
                
                
                
                
                
                
                
                
                
                
                
                
                <mesh filename="b_WheelTurner_001_.obj"/>
                
                
                
                
                
                
                
            
            
            
            
            
            
            
            </geometry>
            
            
            
            
            
            
            
        
        
        
        
        
        
        
        </visual>
        
        
        
        
        
        
        
        
        
        
        
        
        
        
        <inertial>
            
            
            
            
            
            
            
            
            
            
            
            
            
            
            <mass value="1"/>
            
            
            
            
            
            
            
            
            
            
            
            
            
            
            <origin xyz="0 0 0"/>
            
            
            
            
            
            
            
            
            
            
            
            
            
            
            <inertia ixx="1065.454346" ixy="-0.000000" ixz="-0.000000" iyy="977.780767" iyz="94.756588" izz="430.317097"/>
            
            
            
            
            
            
            
        
        
        
        
        
        
        
        </inertial>
        
        
        
        
        
        
        
        
        
        
        
        
        
        
        <collision>
            
            
            
            
            
            
            
            
            
            
            
            
            
            
            <geometry>
                
                
                
                
                
                
                
                
                
                
                
                
                
                
                <mesh filename="b_WheelTurner_001_.obj"/>
                
                
                
                
                
                
                
            
            
            
            
            
            
            
            </geometry>
            
            
            
            
            
            
            
            
            
            
            
            
            
            
            <origin xyz="47.1506 10.0 -8.006339732172128" rpy="0 0 0"/>
            
            
            
            
            
            
            
        
        
        
        
        
        
        
        </collision>
        
        
        
        
        
        
        
    
    
    
    
    
    
    
    </link>
    
    
    
    
    
    
    

    
    
    
    
    
    
    <joint name="Revolute_continuous_004" type="continuous">
        
        
        
        
        
        
        
        
        
        
        
        
        <parent link="b_CraneBody2_001_"/>
        
        
        
        
        
        
        
        
        
        
        
        
        <child link="b_WheelTurner_001_001"/>
        
        
        
        
        
        
        
        
        
        
        
        
        <origin rpy="0 0 0" xyz="-47.1506 -30.0 8.006339732172123"/>
        
        
        
        
        
        
        
        
        
        
        
        
        <axis xyz="0.0 0.0 1.0"/>
        
        
        
        
        
        
        
        
        
        
        
        
        <limit velocity="10000000"/>
        
        
        
        
        
        
    
    
    
    
    
    
    </joint>
    
    
    
    
    
    
    
    
    
    
    
    
    <link name="b_WheelTurner_001_001">
        
        
        
        
        
        
        
        
        
        
        
        
        <visual>
            
            
            
            
            
            
            
            
            
            
            
            
            <origin xyz="47.1506 30.0 -8.006339732172123" rpy="0 0 0"/>
            
            
            
            
            
            
            
            
            
            
            
            
            <geometry>
                
                
                
                
                
                
                
                
                
                
                
                
                <mesh filename="b_WheelTurner_001_001.obj"/>
                
                
                
                
                
                
            
            
            
            
            
            
            </geometry>
            
            
            
            
            
            
        
        
        
        
        
        
        </visual>
        
        
        
        
        
        
        
        
        
        
        
        
        <inertial>
            
            
            
            
            
            
            
            
            
            
            
            
            <mass value="1"/>
            
            
            
            
            
            
            
            
            
            
            
            
            <origin xyz="0 0 0"/>
            
            
            
            
            
            
            
            
            
            
            
            
            <inertia ixx="1065.454346" ixy="0.000000" ixz="-0.000000" iyy="977.780767" iyz="-94.756588" izz="430.317097"/>
            
            
            
            
            
            
        
        
        
        
        
        
        </inertial>
        
        
        
        
        
        
        
        
        
        
        
        
        <collision>
            
            
            
            
            
            
            
            
            
            
            
            
            <geometry>
                
                
                
                
                
                
                
                
                
                
                
                
                <mesh filename="b_WheelTurner_001_001.obj"/>
                
                
                
                
                
                
            
            
            
            
            
            
            </geometry>
            
            
            
            
            
            
            
            
            
            
            
            
            <origin xyz="47.1506 30.0 -8.006339732172123" rpy="0 0 0"/>
            
            
            
            
            
            
        
        
        
        
        
        
        </collision>
        
        
        
        
        
        
    
    
    
    
    
    
    </link>
    
    
    
    
    
    

    
    
    
    
    
    <joint name="Revolute_continuous_005" type="continuous">
        
        
        
        
        
        
        
        
        
        
        <parent link="b_CraneBody2_001_"/>
        
        
        
        
        
        
        
        
        
        
        <child link="b_WheelTurner_001_002"/>
        
        
        
        
        
        
        
        
        
        
        <origin rpy="0 0 0" xyz="17.254223 -10.0 8.006339732172128"/>
        
        
        
        
        
        
        
        
        
        
        <axis xyz="0.0 0.0 1.0"/>
        
        
        
        
        
        
        
        
        
        
        <limit velocity="10000000"/>
        
        
        
        
        
    
    
    
    
    
    </joint>
    
    
    
    
    
    
    
    
    
    
    <link name="b_WheelTurner_001_002">
        
        
        
        
        
        
        
        
        
        
        <visual>
            
            
            
            
            
            
            
            
            
            
            <origin xyz="-17.254223 10.0 -8.006339732172128" rpy="0 0 0"/>
            
            
            
            
            
            
            
            
            
            
            <geometry>
                
                
                
                
                
                
                
                
                
                
                <mesh filename="b_WheelTurner_001_002.obj"/>
                
                
                
                
                
            
            
            
            
            
            </geometry>
            
            
            
            
            
        
        
        
        
        
        </visual>
        
        
        
        
        
        
        
        
        
        
        <inertial>
            
            
            
            
            
            
            
            
            
            
            <mass value="1"/>
            
            
            
            
            
            
            
            
            
            
            <origin xyz="0 0 0"/>
            
            
            
            
            
            
            
            
            
            
            <inertia ixx="1065.454346" ixy="0.000000" ixz="-0.000000" iyy="977.780767" iyz="94.756588" izz="430.317097"/>
            
            
            
            
            
        
        
        
        
        
        </inertial>
        
        
        
        
        
        
        
        
        
        
        <collision>
            
            
            
            
            
            
            
            
            
            
            <geometry>
                
                
                
                
                
                
                
                
                
                
                <mesh filename="b_WheelTurner_001_002.obj"/>
                
                
                
                
                
            
            
            
            
            
            </geometry>
            
            
            
            
            
            
            
            
            
            
            <origin xyz="-17.254223 10.0 -8.006339732172128" rpy="0 0 0"/>
            
            
            
            
            
        
        
        
        
        
        </collision>
        
        
        
        
        
    
    
    
    
    
    </link>
    
    
    
    
    

    
    
    
    
    <joint name="Revolute_continuous_006" type="continuous">
        
        
        
        
        
        
        
        
        <parent link="b_CraneBody2_001_"/>
        
        
        
        
        
        
        
        
        <child link="b_WheelTurner_001_003"/>
        
        
        
        
        
        
        
        
        <origin rpy="0 0 0" xyz="17.254223 -30.0 8.006339732172123"/>
        
        
        
        
        
        
        
        
        <axis xyz="0.0 0.0 1.0"/>
        
        
        
        
        
        
        
        
        <limit velocity="10000000"/>
        
        
        
        
    
    
    
    
    </joint>
    
    
    
    
    
    
    
    
    <link name="b_WheelTurner_001_003">
        
        
        
        
        
        
        
        
        <visual>
            
            
            
            
            
            
            
            
            <origin xyz="-17.254223 30.0 -8.006339732172123" rpy="0 0 0"/>
            
            
            
            
            
            
            
            
            <geometry>
                
                
                
                
                
                
                
                
                <mesh filename="b_WheelTurner_001_003.obj"/>
                
                
                
                
            
            
            
            
            </geometry>
            
            
            
            
        
        
        
        
        </visual>
        
        
        
        
        
        
        
        
        <inertial>
            
            
            
            
            
            
            
            
            <mass value="1"/>
            
            
            
            
            
            
            
            
            <origin xyz="0 0 0"/>
            
            
            
            
            
            
            
            
            <inertia ixx="1065.454346" ixy="0.000000" ixz="-0.000000" iyy="977.780767" iyz="-94.756588" izz="430.317097"/>
            
            
            
            
        
        
        
        
        </inertial>
        
        
        
        
        
        
        
        
        <collision>
            
            
            
            
            
            
            
            
            <geometry>
                
                
                
                
                
                
                
                
                <mesh filename="b_WheelTurner_001_003.obj"/>
                
                
                
                
            
            
            
            
            </geometry>
            
            
            
            
            
            
            
            
            <origin xyz="-17.254223 30.0 -8.006339732172123" rpy="0 0 0"/>
            
            
            
            
        
        
        
        
        </collision>
        
        
        
        
    
    
    
    
    </link>
    
    
    
    

    
    
    
    <joint name="Revolute_continuous_007" type="continuous">
        
        
        
        
        
        
        <parent link="b_WheelTurner_001_001"/>
        
        
        
        
        
        
        <child link="b_Wheel_001_"/>
        
        
        
        
        
        
        <origin rpy="0 0 0" xyz="8.613966429038555e-09 -3.96159508184671 -6.829780125604741"/>
        
        
        
        
        
        
        <axis xyz="0.0 -1.0 -4.440892098500626e-16"/>
        
        
        
        
        
        
        <limit velocity="10000000"/>
        
        
        
    
    
    
    </joint>
    
    
    
    
    
    
    <link name="b_Wheel_001_">
        
        
        
        
        
        
        <visual>
            
            
            
            
            
            
            <origin xyz="47.15059999138603 33.96159508184671 -1.1765596065673813" rpy="0 0 0"/>
            
            
            
            
            
            
            <geometry>
                
                
                
                
                
                
                <mesh filename="b_Wheel_001_.obj"/>
                
                
                
            
            
            
            </geometry>
            
            
            
        
        
        
        </visual>
        
        
        
        
        
        
        <inertial>
            
            
            
            
            
            
            <mass value="1"/>
            
            
            
            
            
            
            <origin xyz="0 0 0"/>
            
            
            
            
            
            
            <inertia ixx="18671.295034" ixy="-0.000000" ixz="0.000000" iyy="32809.570888" iyz="-0.000000" izz="18671.295034"/>
            
            
            
        
        
        
        </inertial>
        
        
        
        
        
        
        <collision>
            
            
            
            
            
            
            <geometry>
                
                
                
                
                
                
                <mesh filename="b_Wheel_001_.obj"/>
                
                
                
            
            
            
            </geometry>
            
            
            
            
            
            
            <origin xyz="47.15059999138603 33.96159508184671 -1.1765596065673813" rpy="0 0 0"/>
            
            
            
        
        
        
        </collision>
        
        
        
    
    
    
    </link>
    
    
    

    
    
    <joint name="Revolute_continuous_008" type="continuous">
        
        
        
        
        <parent link="b_WheelTurner_001_"/>
        
        
        
        
        <child link="b_Wheel_001_001"/>
        
        
        
        
        <origin rpy="0 0 0" xyz="7.694197279306536e-09 3.961595065308847 -6.790279698358648"/>
        
        
        
        
        <axis xyz="0.0 -1.0 -2.220446049250313e-16"/>
        
        
        
        
        <limit velocity="10000000"/>
        
        
    
    
    </joint>
    
    
    
    
    <link name="b_Wheel_001_001">
        
        
        
        
        <visual>
            
            
            
            
            <origin xyz="47.1505999923058 6.038404934691153 -1.2160600338134797" rpy="0 0 0"/>
            
            
            
            
            <geometry>
                
                
                
                
                <mesh filename="b_Wheel_001_001.obj"/>
                
                
            
            
            </geometry>
            
            
        
        
        </visual>
        
        
        
        
        <inertial>
            
            
            
            
            <mass value="1"/>
            
            
            
            
            <origin xyz="0 0 0"/>
            
            
            
            
            <inertia ixx="18671.295034" ixy="-0.000000" ixz="0.000000" iyy="32809.570888" iyz="-0.000000" izz="18671.295034"/>
            
            
        
        
        </inertial>
        
        
        
        
        <collision>
            
            
            
            
            <geometry>
                
                
                
                
                <mesh filename="b_Wheel_001_001.obj"/>
                
                
            
            
            </geometry>
            
            
            
            
            <origin xyz="47.1505999923058 6.038404934691153 -1.2160600338134797" rpy="0 0 0"/>
            
            
        
        
        </collision>
        
        
    
    
    </link>
    
    

    
    <joint name="Revolute_continuous_009" type="continuous">
        
        
        <parent link="b_WheelTurner_001_003"/>
        
        
        <child link="b_Wheel_001_002"/>
        
        
        <origin rpy="0 0 0" xyz="1.1148724610166028e-08 -3.9615950868764074 -6.897370457635998"/>
        
        
        <axis xyz="0.0 -1.0 -2.220446049250313e-16"/>
        
        
        <limit velocity="10000000"/>
        
    
    </joint>
    
    
    <link name="b_Wheel_001_002">
        
        
        <visual>
            
            
            <origin xyz="-17.254223011148724 33.96159508687641 -1.1089692745361246" rpy="0 0 0"/>
            
            
            <geometry>
                
                
                <mesh filename="b_Wheel_001_002.obj"/>
                
            
            </geometry>
            
        
        </visual>
        
        
        <inertial>
            
            
            <mass value="1"/>
            
            
            <origin xyz="0 0 0"/>
            
            
            <inertia ixx="18671.295034" ixy="-0.000000" ixz="0.000000" iyy="32809.570888" iyz="-0.000000" izz="18671.295034"/>
            
        
        </inertial>
        
        
        <collision>
            
            
            <geometry>
                
                
                <mesh filename="b_Wheel_001_002.obj"/>
                
            
            </geometry>
            
            
            <origin xyz="-17.254223011148724 33.96159508687641 -1.1089692745361246" rpy="0 0 0"/>
            
        
        </collision>
        
    
    </link>
    

    <joint name="Revolute_continuous_010" type="continuous">
        <parent link="b_WheelTurner_001_002"/>
        <child link="b_Wheel_001_003"/>
        <origin rpy="0 0 0" xyz="-1.3272572374489755e-08 3.961595064488341 -6.89769144056904"/>
        <axis xyz="0.0 -1.0 -2.220446049250313e-16"/>
        <limit velocity="10000000"/>
    </joint>
    <link name="b_Wheel_001_003">
        <visual>
            <origin xyz="-17.254222986727427 6.038404935511659 -1.108648291603088" rpy="0 0 0"/>
            <geometry>
                <mesh filename="b_Wheel_001_003.obj"/>
            </geometry>
        </visual>
        <inertial>
            <mass value="1"/>
            <origin xyz="0 0 0"/>
            <inertia ixx="18671.295034" ixy="-0.000000" ixz="0.000000" iyy="32809.570888" iyz="-0.000000" izz="18671.295034"/>
        </inertial>
        <collision>
            <geometry>
                <mesh filename="b_Wheel_001_003.obj"/>
            </geometry>
            <origin xyz="-17.254222986727427 6.038404935511659 -1.108648291603088" rpy="0 0 0"/>
        </collision>
    </link>
</robot>
